setblock ~0 ~0 ~0 dark_oak_wood keep
setblock ~-1 ~0 ~0 dark_oak_wood keep
setblock ~-2 ~0 ~0 dark_oak_stairs ["weirdo_direction"=1, "upside_down_bit"=false] keep
setblock ~1 ~0 ~0 dark_oak_stairs ["weirdo_direction"=0, "upside_down_bit"=false] keep
setblock ~0 ~0 ~1 dark_oak_wood keep
setblock ~0 ~1 ~1 dark_oak_stairs ["weirdo_direction"=2, "upside_down_bit"=false] keep
setblock ~-1 ~0 ~-1 dark_oak_wood keep
setblock ~0 ~1 ~0 dark_oak_log ["pillar_axis"="y"] keep
setblock ~0 ~2 ~0 dark_oak_log ["pillar_axis"="y"] keep
setblock ~0 ~3 ~0 dark_oak_log ["pillar_axis"="y"] keep
setblock ~0 ~4 ~0 dark_oak_stairs ["weirdo_direction"=1, "upside_down_bit"=true] keep
setblock ~1 ~4 ~0 dark_oak_log ["pillar_axis"="y"] keep
setblock ~2 ~4 ~0 dark_oak_log ["pillar_axis"="x"] keep
setblock ~3 ~4 ~0 dark_oak_fence keep
setblock ~1 ~5 ~-1 dark_oak_log ["pillar_axis"="z"] keep
setblock ~1 ~5 ~-2 dark_oak_fence keep
setblock ~0 ~5 ~0 dark_oak_log ["pillar_axis"="y"] keep
setblock ~-1 ~6 ~0 dark_oak_fence keep
setblock ~4 ~3 ~0 dark_oak_leaves ["persistent_bit"=true] keep
fill ~3 ~4 ~-1 ~5 ~5 ~1 dark_oak_leaves ["persistent_bit"=true] replace air
fill ~4 ~4 ~-2 ~4 ~5 ~2 dark_oak_leaves ["persistent_bit"=true] replace air
setblock ~4 ~6 ~0 dark_oak_leaves ["persistent_bit"=true] keep
setblock ~1 ~4 ~-3 dark_oak_leaves ["persistent_bit"=true] keep
fill ~0 ~5 ~-4 ~2 ~6 ~-2 dark_oak_leaves ["persistent_bit"=true] replace air
setblock ~1 ~7 ~-3 dark_oak_leaves ["persistent_bit"=true] keep
setblock ~-1 ~5 ~0 dark_oak_leaves ["persistent_bit"=true] keep
setblock ~-1 ~5 ~1 dark_oak_leaves ["persistent_bit"=true] keep
fill ~-2 ~6 ~-1 ~0 ~8 ~1 dark_oak_leaves ["persistent_bit"=true] replace air
fill ~-1 ~6 ~-2 ~-1 ~8 ~2 dark_oak_leaves ["persistent_bit"=true] replace air
setblock ~-1 ~9 ~0 dark_oak_leaves ["persistent_bit"=true] keep
setblock ~-2 ~9 ~0 dark_oak_leaves ["persistent_bit"=true] keep
setblock ~0 ~9 ~0 dark_oak_leaves ["persistent_bit"=true] keep
setblock ~-1 ~9 ~-1 dark_oak_leaves ["persistent_bit"=true] keep
setblock ~-1 ~9 ~1 dark_oak_leaves ["persistent_bit"=true] keep
setblock ~3 ~2 ~0 lantern ["hanging"=true] keep
setblock ~3 ~3 ~0 iron_chain ["pillar_axis"="y"] keep
setblock ~1 ~3 ~-3 iron_chain ["pillar_axis"="y"] keep
setblock ~1 ~2 ~-3 lantern ["hanging"=true] keep
setblock ~-1 ~4 ~0 lantern ["hanging"=true] keep
setblock ~-1 ~5 ~0 iron_chain ["pillar_axis"="y"] keep