setblock ~0 ~0 ~0 dark_oak_wood keep
setblock ~1 ~0 ~1 dark_oak_wood keep
setblock ~-1 ~0 ~0 dark_oak_wood keep
setblock ~2 ~0 ~2 dark_oak_stairs ["weirdo_direction"=0, "upside_down_bit"=false] keep
setblock ~-2 ~0 ~0 dark_oak_stairs ["weirdo_direction"=1, "upside_down_bit"=false] keep
setblock ~-1 ~0 ~-1 dark_oak_stairs ["weirdo_direction"=3, "upside_down_bit"=false] keep
setblock ~1 ~1 ~1 dark_oak_stairs ["weirdo_direction"=2, "upside_down_bit"=false] keep
setblock ~0 ~1 ~0 dark_oak_log ["pillar_axis"="y"] keep
setblock ~0 ~2 ~0 dark_oak_log ["pillar_axis"="y"] keep
setblock ~0 ~3 ~0 dark_oak_stairs ["weirdo_direction"=1, "upside_down_bit"=true] keep
setblock ~-1 ~3 ~0 dark_oak_log ["pillar_axis"="x"] keep
setblock ~-2 ~3 ~0 dark_oak_fence keep
setblock ~-3 ~4 ~0 dark_oak_fence keep
setblock ~0 ~3 ~1 dark_oak_stairs ["weirdo_direction"=2, "upside_down_bit"=true] keep
setblock ~0 ~4 ~1 dark_oak_log ["pillar_axis"="z"] keep
setblock ~0 ~4 ~2 dark_oak_log ["pillar_axis"="z"] keep
setblock ~0 ~4 ~3 dark_oak_fence keep
setblock ~0 ~3 ~0 dark_oak_log ["pillar_axis"="y"] keep
setblock ~0 ~4 ~0 dark_oak_log ["pillar_axis"="y"] keep
setblock ~-3 ~3 ~0 dark_oak_leaves ["persistent_bit"=true] keep
fill ~-4 ~4 ~0 ~-2 ~5 ~0 dark_oak_leaves ["persistent_bit"=true] replace air
setblock ~-3 ~4 ~1 dark_oak_leaves ["persistent_bit"=true] keep
setblock ~-3 ~4 ~-1 dark_oak_leaves ["persistent_bit"=true] keep
setblock ~-3 ~6 ~0 dark_oak_leaves ["persistent_bit"=true] keep
setblock ~0 ~3 ~3 dark_oak_leaves ["persistent_bit"=true] keep
fill ~-1 ~4 ~3 ~1 ~5 ~3 dark_oak_leaves ["persistent_bit"=true] replace air
setblock ~0 ~4 ~2 dark_oak_leaves ["persistent_bit"=true] keep
setblock ~0 ~4 ~4 dark_oak_leaves ["persistent_bit"=true] keep
setblock ~0 ~6 ~3 dark_oak_leaves ["persistent_bit"=true] keep
setblock ~0 ~4 ~0 dark_oak_leaves ["persistent_bit"=true] keep
fill ~-1 ~5 ~-1 ~1 ~6 ~1 dark_oak_leaves ["persistent_bit"=true] replace air
setblock ~-1 ~5 ~-1 dark_oak_leaves ["persistent_bit"=true] keep
setblock ~1 ~5 ~1 dark_oak_leaves ["persistent_bit"=true] keep
setblock ~0 ~7 ~0 dark_oak_leaves ["persistent_bit"=true] keep
setblock ~1 ~7 ~0 dark_oak_leaves ["persistent_bit"=true] keep
setblock ~-1 ~7 ~0 dark_oak_leaves ["persistent_bit"=true] keep
setblock ~-3 ~2 ~0 lantern ["hanging"=true] keep
setblock ~0 ~3 ~3 iron_chain ["pillar_axis"="y"] keep
setblock ~0 ~2 ~3 lantern ["hanging"=true] keep
setblock ~0 ~4 ~-1 lantern ["hanging"=true] keep